Workbook

Sheet README
A1: G6x Timing Template: standard blocks instead of copy-paste
A3: How it works
A4: 1. Blocks: the standard task sequences (mold launch, mold change, PPAP), with roles, durations and logic. Owned centrally, versioned.
A5: 2. Team: one role -> person map per project. Blocks never name people.
A6: 3. Inputs: per mold only press, part numbers, delivery date, gauge validation date and the TH1 trial slot (blue cells).
A7: 4. Plan: generated from the three sheets above. All dates are formulas: change an input or a duration and everything after it moves.
A8: 5. Project-specific tasks (customer trials, downtime, payment setup...) are planned by hand on top; they are not in the blocks.
A10: Rules
A11: - Workdays Mon-Fri; plant holidays go on the Holidays sheet.
A12: - Cpk and iPQ elements are checklists on one task, not one row per characteristic / element.
A13: - Mold engineering changes are ECRs: plan them in the plm2 change plan; the project shows only their milestones.
A14: - 'PM plan' columns hold the dates from G6x Project Timeline (2026-09-30).mpp for comparison; 'Delta' = template finish minus PM finish (calendar days).
... A17: Source: G6x Project Timeline (2026-09-30).mpp, PM 1748, read 2026-10-02.

Sheet Team
A1: Role | B1: Person | C1: Department
A2: Program Manager | B2: Steven Stocks | C2: Program Mgmt
A3: Plant Layout | B3: Stacy Sexton | C3: Plant Engineering
A4: Toolshop | B4: Brandon Belk | C4: Toolshop
A5: Gauge / Metrology | B5: Erica Gibson | C5: Quality
A6: CMM Lab | B6: Erika Harris | C6: Quality
A7: Trial Lead | B7: Christopher Holmes | C7: Process Engineering
A8: Process Engineer (WI) | B8: Scott Damewood | C8: Process Engineering
A9: Packaging | B9: Kenny Rice | C9: Logistics
A10: Quality Engineer | B10: Apurva Mhetre | C10: Quality
A11: Production Planning | B11: Alexa Earls | C11: Production
A12: Doc Control / ERP | B12: Todd Haynes | C12: Engineering
... A15: Press / Plant Eng | B15: Huascar Miranda | C15: Plant Engineering

Sheet Plan
A1: Mold | B1: Step ID | C1: Task | D1: Role | E1: Person | F1: Duration (wd) | G1: Start | H1: Finish | I1: PM plan start | J1: PM plan finish | K1: Delta finish (days) | L1: Checklist
A2: =Inputs!A2 | C2: =Inputs!B2&": Mold "&Inputs!A2&" ("&Inputs!C2&")" | G2: =MIN(G3:G13) | H2: =MAX(H3:H13)
A3: =Inputs!A2 | B3: =Blocks!B3 | C3: =Blocks!C3 | D3: =Blocks!D3 | E3: =IFERROR(INDEX(Team!$B$2:$B$60,MATCH(D3,Team!$A$2:$A$60,0)),"(assign)") | F3: =Blocks!E3 | G3: =WORKDAY(G5,-F3,Holidays!$A$2:$A$60) | H3: =IF(F3=0,G3,WORKDAY(G3,F3-1,Holidays!$A$2:$A$60)) | L3: =IF(Blocks!H3="","",Blocks!H3)
A4: =Inputs!A2 | B4: =Blocks!B4 | C4: =Blocks!C4 | D4: =Blocks!D4 | E4: =IFERROR(INDEX(Team!$B$2:$B$60,MATCH(D4,Team!$A$2:$A$60,0)),"(assign)") | F4: =Blocks!E4 | G4: =Inputs!D2 | H4: =IF(F4=0,G4,WORKDAY(G4,F4-1,Holidays!$A$2:$A$60)) | L4: =IF(Blocks!H4="","",Blocks!H4)
A5: =Inputs!A2 | B5: =Blocks!B5 | C5: =Blocks!C5 | D5: =Blocks!D5 | E5: =IFERROR(INDEX(Team!$B$2:$B$60,MATCH(D5,Team!$A$2:$A$60,0)),"(assign)") | F5: =Blocks!E5 | G5: =MAX(WORKDAY(H4,1,Holidays!$A$2:$A$60)) | H5: =IF(F5=0,G5,WORKDAY(G5,F5-1,Holidays!$A$2:$A$60)) | I5: 46245 | J5: 46246 | K5: =IF(J5="","",H5-J5) | L5: =IF(Blocks!H5="","",Blocks!H5)
A6: =Inputs!A2 | B6: =Blocks!B6 | C6: =Blocks!C6 | D6: =Blocks!D6 | E6: =IFERROR(INDEX(Team!$B$2:$B$60,MATCH(D6,Team!$A$2:$A$60,0)),"(assign)") | F6: =Blocks!E6 | G6: =IF(Inputs!E2="",MAX(WORKDAY(H5,1,Holidays!$A$2:$A$60)),Inputs!E2) | H6: =IF(F6=0,G6,WORKDAY(G6,F6-1,Holidays!$A$2:$A$60)) | L6: =IF(Blocks!H6="","",Blocks!H6)
A7: =Inputs!A2 | B7: =Blocks!B7 | C7: =Blocks!C7 | D7: =Blocks!D7 | E7: =IFERROR(INDEX(Team!$B$2:$B$60,MATCH(D7,Team!$A$2:$A$60,0)),"(assign)") | F7: =Blocks!E7 | G7: =MAX(Inputs!F2,WORKDAY(H5,1,Holidays!$A$2:$A$60),WORKDAY(H6,1,Holidays!$A$2:$A$60)) | H7: =IF(F7=0,G7,WORKDAY(G7,F7-1,Holidays!$A$2:$A$60)) | I7: 46302 | J7: 46302 | K7: =IF(J7="","",H7-J7) | L7: =IF(Blocks!H7="","",Blocks!H7)
A8: =Inputs!A2 | B8: =Blocks!B8 | C8: =Blocks!C8 | D8: =Blocks!D8 | E8: =IFERROR(INDEX(Team!$B$2:$B$60,MATCH(D8,Team!$A$2:$A$60,0)),"(assign)") | F8: =Blocks!E8 | G8: =MAX(WORKDAY(H7,1,Holidays!$A$2:$A$60)) | H8: =IF(F8=0,G8,WORKDAY(G8,F8-1,Holidays!$A$2:$A$60)) | I8: 46303 | J8: 46315 | K8: =IF(J8="","",H8-J8) | L8: =IF(Blocks!H8="","",Blocks!H8)
A9: =Inputs!A2 | B9: =Blocks!B9 | C9: =Blocks!C9 | D9: =Blocks!D9 | E9: =IFERROR(INDEX(Team!$B$2:$B$60,MATCH(D9,Team!$A$2:$A$60,0)),"(assign)") | F9: =Blocks!E9 | G9: =MAX(WORKDAY(H8,1,Holidays!$A$2:$A$60)) | H9: =IF(F9=0,G9,WORKDAY(G9,F9-1,Holidays!$A$2:$A$60)) | I9: 46316 | J9: 46316 | K9: =IF(J9="","",H9-J9) | L9: =IF(Blocks!H9="","",Blocks!H9)
A10: =Inputs!A2 | B10: =Blocks!B10 | C10: =Blocks!C10 | D10: =Blocks!D10 | E10: =IFERROR(INDEX(Team!$B$2:$B$60,MATCH(D10,Team!$A$2:$A$60,0)),"(assign)") | F10: =Blocks!E10 | G10: =G9 | H10: =IF(F10=0,G10,WORKDAY(G10,F10-1,Holidays!$A$2:$A$60)) | L10: =IF(Blocks!H10="","",Blocks!H10)
A11: =Inputs!A2 | B11: =Blocks!B11 | C11: =Blocks!C11 | D11: =Blocks!D11 | E11: =IFERROR(INDEX(Team!$B$2:$B$60,MATCH(D11,Team!$A$2:$A$60,0)),"(assign)") | F11: =Blocks!E11 | G11: =MAX(WORKDAY(H9,1,Holidays!$A$2:$A$60)) | H11: =IF(F11=0,G11,WORKDAY(G11,F11-1,Holidays!$A$2:$A$60)) | I11: 46317 | J11: 46318 | K11: =IF(J11="","",H11-J11) | L11: =IF(Blocks!H11="","",Blocks!H11)
A12: =Inputs!A2 | B12: =Blocks!B12 | C12: =Blocks!C12 | D12: =Blocks!D12 | E12: =IFERROR(INDEX(Team!$B$2:$B$60,MATCH(D12,Team!$A$2:$A$60,0)),"(assign)") | F12: =Blocks!E12 | G12: =MAX(WORKDAY(H9,1,Holidays!$A$2:$A$60)) | H12: =IF(F12=0,G12,WORKDAY(G12,F12-1,Holidays!$A$2:$A$60)) | I12: 46317 | J12: 46322 | K12: =IF(J12="","",H12-J12) | L12: =IF(Blocks!H12="","",Blocks!H12)
A13: =Inputs!A2 | B13: =Blocks!B13 | C13: =Blocks!C13 | D13: =Blocks!D13 | E13: =IFERROR(INDEX(Team!$B$2:$B$60,MATCH(D13,Team!$A$2:$A$60,0)),"(assign)") | F13: =Blocks!E13 | G13: =MAX(H10,H11,H12) | H13: =IF(F13=0,G13,WORKDAY(G13,F13-1,Holidays!$A$2:$A$60)) | L13: =IF(Blocks!H13="","",Blocks!H13)
A14: =Inputs!A3 | C14: =Inputs!B3&": Mold "&Inputs!A3&" ("&Inputs!C3&")" | G14: =MIN(G15:G25) | H14: =MAX(H15:H25)
A15: =Inputs!A3 | B15: =Blocks!B3 | C15: =Blocks!C3 | D15: =Blocks!D3 | E15: =IFERROR(INDEX(Team!$B$2:$B$60,MATCH(D15,Team!$A$2:$A$60,0)),"(assign)") | F15: =Blocks!E3 | G15: =WORKDAY(G17,-F15,Holidays!$A$2:$A$60) | H15: =IF(F15=0,G15,WORKDAY(G15,F15-1,Holidays!$A$2:$A$60)) | L15: =IF(Blocks!H3="","",Blocks!H3)
A16: =Inputs!A3 | B16: =Blocks!B4 | C16: =Blocks!C4 | D16: =Blocks!D4 | E16: =IFERROR(INDEX(Team!$B$2:$B$60,MATCH(D16,Team!$A$2:$A$60,0)),"(assign)") | F16: =Blocks!E4 | G16: =Inputs!D3 | H16: =IF(F16=0,G16,WORKDAY(G16,F16-1,Holidays!$A$2:$A$60)) | L16: =IF(Blocks!H4="","",Blocks!H4)
A17: =Inputs!A3 | B17: =Blocks!B5 | C17: =Blocks!C5 | D17: =Blocks!D5 | E17: =IFERROR(INDEX(Team!$B$2:$B$60,MATCH(D17,Team!$A$2:$A$60,0)),"(assign)") | F17: =Blocks!E5 | G17: =MAX(WORKDAY(H16,1,Holidays!$A$2:$A$60)) | H17: =IF(F17=0,G17,WORKDAY(G17,F17-1,Holidays!$A$2:$A$60)) | I17: 46269 | J17: 46272 | K17: =IF(J17="","",H17-J17) | L17: =IF(Blocks!H5="","",Blocks!H5)
A18: =Inputs!A3 | B18: =Blocks!B6 | C18: =Blocks!C6 | D18: =Blocks!D6 | E18: =IFERROR(INDEX(Team!$B$2:$B$60,MATCH(D18,Team!$A$2:$A$60,0)),"(assign)") | F18: =Blocks!E6 | G18: =IF(Inputs!E3="",MAX(WORKDAY(H17,1,Holidays!$A$2:$A$60)),Inputs!E3) | H18: =IF(F18=0,G18,WORKDAY(G18,F18-1,Holidays!$A$2:$A$60)) | L18: =IF(Blocks!H6="","",Blocks!H6)
A19: =Inputs!A3 | B19: =Blocks!B7 | C19: =Blocks!C7 | D19: =Blocks!D7 | E19: =IFERROR(INDEX(Team!$B$2:$B$60,MATCH(D19,Team!$A$2:$A$60,0)),"(assign)") | F19: =Blocks!E7 | G19: =MAX(Inputs!F3,WORKDAY(H17,1,Holidays!$A$2:$A$60),WORKDAY(H18,1,Holidays!$A$2:$A$60)) | H19: =IF(F19=0,G19,WORKDAY(G19,F19-1,Holidays!$A$2:$A$60)) | I19: 46303 | J19: 46303 | K19: =IF(J19="","",H19-J19) | L19: =IF(Blocks!H7="","",Blocks!H7)
A20: =Inputs!A3 | B20: =Blocks!B8 | C20: =Blocks!C8 | D20: =Blocks!D8 | E20: =IFERROR(INDEX(Team!$B$2:$B$60,MATCH(D20,Team!$A$2:$A$60,0)),"(assign)") | F20: =Blocks!E8 | G20: =MAX(WORKDAY(H19,1,Holidays!$A$2:$A$60)) | H20: =IF(F20=0,G20,WORKDAY(G20,F20-1,Holidays!$A$2:$A$60)) | I20: 46304 | J20: 46316 | K20: =IF(J20="","",H20-J20) | L20: =IF(Blocks!H8="","",Blocks!H8)
A21: =Inputs!A3 | B21: =Blocks!B9 | C21: =Blocks!C9 | D21: =Blocks!D9 | E21: =IFERROR(INDEX(Team!$B$2:$B$60,MATCH(D21,Team!$A$2:$A$60,0)),"(assign)") | F21: =Blocks!E9 | G21: =MAX(WORKDAY(H20,1,Holidays!$A$2:$A$60)) | H21: =IF(F21=0,G21,WORKDAY(G21,F21-1,Holidays!$A$2:$A$60)) | I21: 46317 | J21: 46317 | K21: =IF(J21="","",H21-J21) | L21: =IF(Blocks!H9="","",Blocks!H9)
A22: =Inputs!A3 | B22: =Blocks!B10 | C22: =Blocks!C10 | D22: =Blocks!D10 | E22: =IFERROR(INDEX(Team!$B$2:$B$60,MATCH(D22,Team!$A$2:$A$60,0)),"(assign)") | F22: =Blocks!E10 | G22: =G21 | H22: =IF(F22=0,G22,WORKDAY(G22,F22-1,Holidays!$A$2:$A$60)) | L22: =IF(Blocks!H10="","",Blocks!H10)
A23: =Inputs!A3 | B23: =Blocks!B11 | C23: =Blocks!C11 | D23: =Blocks!D11 | E23: =IFERROR(INDEX(Team!$B$2:$B$60,MATCH(D23,Team!$A$2:$A$60,0)),"(assign)") | F23: =Blocks!E11 | G23: =MAX(WORKDAY(H21,1,Holidays!$A$2:$A$60)) | H23: =IF(F23=0,G23,WORKDAY(G23,F23-1,Holidays!$A$2:$A$60)) | I23: 46318 | J23: 46321 | K23: =IF(J23="","",H23-J23) | L23: =IF(Blocks!H11="","",Blocks!H11)
A24: =Inputs!A3 | B24: =Blocks!B12 | C24: =Blocks!C12 | D24: =Blocks!D12 | E24: =IFERROR(INDEX(Team!$B$2:$B$60,MATCH(D24,Team!$A$2:$A$60,0)),"(assign)") | F24: =Blocks!E12 | G24: =MAX(WORKDAY(H21,1,Holidays!$A$2:$A$60)) | H24: =IF(F24=0,G24,WORKDAY(G24,F24-1,Holidays!$A$2:$A$60)) | I24: 46318 | J24: 46323 | K24: =IF(J24="","",H24-J24) | L24: =IF(Blocks!H12="","",Blocks!H12)
A25: =Inputs!A3 | B25: =Blocks!B13 | C25: =Blocks!C13 | D25: =Blocks!D13 | E25: =IFERROR(INDEX(Team!$B$2:$B$60,MATCH(D25,Team!$A$2:$A$60,0)),"(assign)") | F25: =Blocks!E13 | G25: =MAX(H22,H23,H24) | H25: =IF(F25=0,G25,WORKDAY(G25,F25-1,Holidays!$A$2:$A$60)) | L25: =IF(Blocks!H13="","",Blocks!H13)
A26: =Inputs!A4 | C26: =Inputs!B4&": Mold "&Inputs!A4&" ("&Inputs!C4&")" | G26: =MIN(G27:G37) | H26: =MAX(H27:H37)
A27: =Inputs!A4 | B27: =Blocks!B3 | C27: =Blocks!C3 | D27: =Blocks!D3 | E27: =IFERROR(INDEX(Team!$B$2:$B$60,MATCH(D27,Team!$A$2:$A$60,0)),"(assign)") | F27: =Blocks!E3 | G27: =WORKDAY(G29,-F27,Holidays!$A$2:$A$60) | H27: =IF(F27=0,G27,WORKDAY(G27,F27-1,Holidays!$A$2:$A$60)) | L27: =IF(Blocks!H3="","",Blocks!H3)
A28: =Inputs!A4 | B28: =Blocks!B4 | C28: =Blocks!C4 | D28: =Blocks!D4 | E28: =IFERROR(INDEX(Team!$B$2:$B$60,MATCH(D28,Team!$A$2:$A$60,0)),"(assign)") | F28: =Blocks!E4 | G28: =Inputs!D4 | H28: =IF(F28=0,G28,WORKDAY(G28,F28-1,Holidays!$A$2:$A$60)) | L28: =IF(Blocks!H4="","",Blocks!H4)
A29: =Inputs!A4 | B29: =Blocks!B5 | C29: =Blocks!C5 | D29: =Blocks!D5 | E29: =IFERROR(INDEX(Team!$B$2:$B$60,MATCH(D29,Team!$A$2:$A$60,0)),"(assign)") | F29: =Blocks!E5 | G29: =MAX(WORKDAY(H28,1,Holidays!$A$2:$A$60)) | H29: =IF(F29=0,G29,WORKDAY(G29,F29-1,Holidays!$A$2:$A$60)) | I29: 46269 | J29: 46272 | K29: =IF(J29="","",H29-J29) | L29: =IF(Blocks!H5="","",Blocks!H5)
A30: =Inputs!A4 | B30: =Blocks!B6 | C30: =Blocks!C6 | D30: =Blocks!D6 | E30: =IFERROR(INDEX(Team!$B$2:$B$60,MATCH(D30,Team!$A$2:$A$60,0)),"(assign)") | F30: =Blocks!E6 | G30: =IF(Inputs!E4="",MAX(WORKDAY(H29,1,Holidays!$A$2:$A$60)),Inputs!E4) | H30: =IF(F30=0,G30,WORKDAY(G30,F30-1,Holidays!$A$2:$A$60)) | L30: =IF(Blocks!H6="","",Blocks!H6)
A31: =Inputs!A4 | B31: =Blocks!B7 | C31: =Blocks!C7 | D31: =Blocks!D7 | E31: =IFERROR(INDEX(Team!$B$2:$B$60,MATCH(D31,Team!$A$2:$A$60,0)),"(assign)") | F31: =Blocks!E7 | G31: =MAX(Inputs!F4,WORKDAY(H29,1,Holidays!$A$2:$A$60),WORKDAY(H30,1,Holidays!$A$2:$A$60)) | H31: =IF(F31=0,G31,WORKDAY(G31,F31-1,Holidays!$A$2:$A$60)) | I31: 46304 | J31: 46304 | K31: =IF(J31="","",H31-J31) | L31: =IF(Blocks!H7="","",Blocks!H7)
A32: =Inputs!A4 | B32: =Blocks!B8 | C32: =Blocks!C8 | D32: =Blocks!D8 | E32: =IFERROR(INDEX(Team!$B$2:$B$60,MATCH(D32,Team!$A$2:$A$60,0)),"(assign)") | F32: =Blocks!E8 | G32: =MAX(WORKDAY(H31,1,Holidays!$A$2:$A$60)) | H32: =IF(F32=0,G32,WORKDAY(G32,F32-1,Holidays!$A$2:$A$60)) | I32: 46307 | J32: 46317 | K32: =IF(J32="","",H32-J32) | L32: =IF(Blocks!H8="","",Blocks!H8)
A33: =Inputs!A4 | B33: =Blocks!B9 | C33: =Blocks!C9 | D33: =Blocks!D9 | E33: =IFERROR(INDEX(Team!$B$2:$B$60,MATCH(D33,Team!$A$2:$A$60,0)),"(assign)") | F33: =Blocks!E9 | G33: =MAX(WORKDAY(H32,1,Holidays!$A$2:$A$60)) | H33: =IF(F33=0,G33,WORKDAY(G33,F33-1,Holidays!$A$2:$A$60)) | I33: 46318 | J33: 46318 | K33: =IF(J33="","",H33-J33) | L33: =IF(Blocks!H9="","",Blocks!H9)
A34: =Inputs!A4 | B34: =Blocks!B10 | C34: =Blocks!C10 | D34: =Blocks!D10 | E34: =IFERROR(INDEX(Team!$B$2:$B$60,MATCH(D34,Team!$A$2:$A$60,0)),"(assign)") | F34: =Blocks!E10 | G34: =G33 | H34: =IF(F34=0,G34,WORKDAY(G34,F34-1,Holidays!$A$2:$A$60)) | L34: =IF(Blocks!H10="","",Blocks!H10)
A35: =Inputs!A4 | B35: =Blocks!B11 | C35: =Blocks!C11 | D35: =Blocks!D11 | E35: =IFERROR(INDEX(Team!$B$2:$B$60,MATCH(D35,Team!$A$2:$A$60,0)),"(assign)") | F35: =Blocks!E11 | G35: =MAX(WORKDAY(H33,1,Holidays!$A$2:$A$60)) | H35: =IF(F35=0,G35,WORKDAY(G35,F35-1,Holidays!$A$2:$A$60)) | I35: 46321 | J35: 46322 | K35: =IF(J35="","",H35-J35) | L35: =IF(Blocks!H11="","",Blocks!H11)
A36: =Inputs!A4 | B36: =Blocks!B12 | C36: =Blocks!C12 | D36: =Blocks!D12 | E36: =IFERROR(INDEX(Team!$B$2:$B$60,MATCH(D36,Team!$A$2:$A$60,0)),"(assign)") | F36: =Blocks!E12 | G36: =MAX(WORKDAY(H33,1,Holidays!$A$2:$A$60)) | H36: =IF(F36=0,G36,WORKDAY(G36,F36-1,Holidays!$A$2:$A$60)) | I36: 46321 | J36: 46324 | K36: =IF(J36="","",H36-J36) | L36: =IF(Blocks!H12="","",Blocks!H12)
A37: =Inputs!A4 | B37: =Blocks!B13 | C37: =Blocks!C13 | D37: =Blocks!D13 | E37: =IFERROR(INDEX(Team!$B$2:$B$60,MATCH(D37,Team!$A$2:$A$60,0)),"(assign)") | F37: =Blocks!E13 | G37: =MAX(H34,H35,H36) | H37: =IF(F37=0,G37,WORKDAY(G37,F37-1,Holidays!$A$2:$A$60)) | L37: =IF(Blocks!H13="","",Blocks!H13)
A38: =Inputs!A5 | C38: =Inputs!B5&": Mold "&Inputs!A5&" ("&Inputs!C5&")" | G38: =MIN(G39:G49) | H38: =MAX(H39:H49)
A39: =Inputs!A5 | B39: =Blocks!B3 | C39: =Blocks!C3 | D39: =Blocks!D3 | E39: =IFERROR(INDEX(Team!$B$2:$B$60,MATCH(D39,Team!$A$2:$A$60,0)),"(assign)") | F39: =Blocks!E3 | G39: =WORKDAY(G41,-F39,Holidays!$A$2:$A$60) | H39: =IF(F39=0,G39,WORKDAY(G39,F39-1,Holidays!$A$2:$A$60)) | L39: =IF(Blocks!H3="","",Blocks!H3)
A40: =Inputs!A5 | B40: =Blocks!B4 | C40: =Blocks!C4 | D40: =Blocks!D4 | E40: =IFERROR(INDEX(Team!$B$2:$B$60,MATCH(D40,Team!$A$2:$A$60,0)),"(assign)") | F40: =Blocks!E4 | G40: =Inputs!D5 | H40: =IF(F40=0,G40,WORKDAY(G40,F40-1,Holidays!$A$2:$A$60)) | L40: =IF(Blocks!H4="","",Blocks!H4)
...

Sheet Blocks
A1: Block | B1: Step ID | C1: Step | D1: Role | E1: Duration (wd) | F1: Depends on | G1: Rule | H1: Checklist / deliverable
A2: LAUNCH: New / transfer mold launch (one per mold)
A3: LAUNCH | B3: L01 | C3: Assign location in plant layout | D3: Plant Layout | E3: 15 | F3: L03 | G3: Finish the workday before L03 starts
A4: LAUNCH | B4: L02 | C4: Mold delivery | D4: Program Manager | E4: 0 | G4: Start = input 'delivery'
A5: LAUNCH | B5: L03 | C5: Unpack / prep | D5: Toolshop | E5: 2 | F5: L02 | G5: Start the workday after L02 finish
A6: LAUNCH | B6: L04 | C6: Gauge validation | D6: Gauge / Metrology | E6: 1 | F6: L03 | G6: Input 'gauge' if given, else after L03
A7: LAUNCH | B7: L05 | C7: TH1 trial | D7: Trial Lead | E7: 1 | F7: L03, L04 | G7: Later of input 'th1' and after L03 and L04
A8: LAUNCH | B8: L06 | C8: Complete work instructions | D8: Process Engineer (WI) | E8: 9 | F8: L05 | G8: Start the workday after L05 finish | H8: WI, first piece & safe launch WI, gauge WI
A9: LAUNCH | B9: L07 | C9: TH2 trial | D9: Trial Lead | E9: 1 | F9: L06 | G9: Start the workday after L06 finish
A10: LAUNCH | B10: L08 | C10: Packaging trial / instruction | D10: Packaging | E10: 1 | F10: L07 | G10: Start the same day as L07 | H10: PDS / packaging instruction
A11: LAUNCH | B11: L09 | C11: 6-pc dimensional (CMM) | D11: CMM Lab | E11: 2 | F11: L07 | G11: Start the workday after L07 finish | H11: all cavities
A12: LAUNCH | B12: L10 | C12: 30-pc Cpk | D12: Quality Engineer | E12: 4 | F12: L07 | G12: Start the workday after L07 finish | H12: Weight; Thickness; every SPC characteristic on the control plan (from PDB)
A13: LAUNCH | B13: L11 | C13: Mold ready for PPAP | D13: Program Manager | E13: 0 | F13: L08, L09, L10 | G13: Milestone when L08, L09, L10 are done
A14: MOLDCHG: Mold engineering change (belongs in the plm2 ECR plan)
A15: MOLDCHG | B15: E01 | C15: Bank build for the change | D15: Production Planning | E15: 10 | F15: E02 | G15: Finish the workday before E02 starts | H15: coverage until changed parts ship
A16: MOLDCHG | B16: E02 | C16: Ship tool to toolmaker | D16: Toolshop | E16: 1 | G16: Start = input 'tool_out'
A17: MOLDCHG | B17: E03 | C17: Tool modification | D17: Tool Engineering | E17: 10 | F17: E02 | G17: Start the workday after E02 finish | H17: duration per quote
A18: MOLDCHG | B18: E04 | C18: Return tool to plant | D18: Toolshop | E18: 1 | F18: E03 | G18: Start the workday after E03 finish
A19: MOLDCHG | B19: E05 | C19: Verify AI level engraved in mold | D19: Toolshop | E19: 1 | F19: E04 | G19: Start the workday after E04 finish
A20: MOLDCHG | B20: E06 | C20: Change AI level in system | D20: Doc Control / ERP | E20: 2 | F20: E03 | G20: Start the same day as E03
A21: MOLDCHG | B21: E07 | C21: TH trial (changed tool) | D21: Trial Lead | E21: 1 | F21: E05, E06 | G21: Start the workday after E05 and E06 finish
A22: MOLDCHG | B22: E08 | C22: 6-pc dimensional (CMM) | D22: CMM Lab | E22: 2 | F22: E07 | G22: Start the workday after E07 finish | H22: all cavities
A23: MOLDCHG | B23: E09 | C23: 30-pc Cpk | D23: Quality Engineer | E23: 4 | F23: E07 | G23: Start the workday after E07 finish | H23: Weight; Thickness; every SPC characteristic on the control plan (from PDB)
A24: MOLDCHG | B24: E10 | C24: Material disposition (old level) | D24: Production Planning | E24: 1 | F24: E07 | G24: Start the same day as E07
A25: MOLDCHG | B25: E11 | C25: Customer part approval / sampling | D25: Program Manager | E25: 1 | F25: E08, E09 | G25: Start the workday after E08 and E09 finish | H25: optional: vehicle trial
A26: MOLDCHG | B26: E12 | C26: Production start-up, new level | D26: Production Planning | E26: 5 | F26: E11 | G26: Start the workday after E11 finish
A27: MOLDCHG | B27: E13 | C27: Changed parts delivered | D27: Program Manager | E27: 0 | F27: E12 | G27: Milestone when E12 are done
A28: PPAP: PPAP / ISIR package (one per part family)
A29: PPAP | B29: P01 | C29: Initial capability (10-pc Cpk) | D29: Quality Engineer | E29: 3 | G29: Start = input 'trial' | H29: Weight; Thickness; every SPC characteristic on the control plan (from PDB)
A30: PPAP | B30: P02 | C30: ISIR / iPQ package | D30: Quality Engineer | E30: 15 | F30: P01 | G30: Start the workday after P01 finish | H30: 0.1 Cover sheet; 0.2 Self-assessment; 1.3 Design/engineering approvals; 1.4 IMDS; 2.1 Process flowchart; 2.2 PFMEA; 2.3 Control plan; 3.1 Geometry/dimensions; 3.2 Material; 3.10 Reliability; 4.6 Tools; 5.1 Legal compliance; 5.4 MSA; 5.5 Part history; 5.6 Load carriers
A31: PPAP | B31: P03 | C31: Validation testing (PV) | D31: Quality Engineer | E31: 60 | F31: P02 | G31: Start the same day as P02 | H31: quote, select lab, ship samples, test
A32: PPAP | B32: P04 | C32: Full PPAP approval | D32: Program Manager | E32: 0 | F32: P02, P03 | G32: Milestone when P02, P03 are done

Sheet Inputs
A1: Mold | B1: Press | C1: Part numbers | D1: Delivery | E1: Gauge validation | F1: TH1 trial slot
A2: 3355 | B2: 900-5 | C2: 5A65DF8-03 | D2: 46244 | E2: 46297 | F2: 46302
A3: 3363 | B3: 1300-3 | C3: 5A65E17-03, 5A65E18-03 | D3: 46268 | E3: 46300 | F3: 46303
A4: 3370 | B4: 1600-2 | C4: 5B533A6-02 | D4: 46268 | E4: 46301 | F4: 46304
A5: 3377 | B5: 1300-2 | C5: 9635313-02, 9635314-02 | D5: 46244 | E5: 46302 | F5: 46308
A6: 3376 | B6: 1300-3 | C6: 9635311-02, 9635312-02 | D6: 46244 | E6: 46309
A7: 3362 | B7: 1600-2 | C7: 5A65E00-03, 5A65E00-04 | D7: 46268 | E7: 46310 | F7: 46310
A8: 3343 | B8: 1600-2 | C8: 5A87904-02, 5A65C28-02 | D8: 46268 | E8: 46310 | F8: 46311
A9: 3347 | B9: 1300-3 | C9: 5B6CA70-04 | D9: 46244 | E9: 46311 | F9: 46315
A10: 3352 | B10: 550 | C10: 5B6CA81-02, 5B6CA82-02 | D10: 46268 | E10: 46314 | F10: 46317

Sheet Holidays
A1: Plant holiday | B1: Name | C1: Enter plant holidays here; all plan dates skip them.

Sheet Findings
A1: Area | B1: Found in the current .mpp | C1: How the template prevents it
A2: Links | B2: 0 of 239 tasks are linked, no constraints, no baseline | C2: Every date is typed by hand; a slip moves nothing and cannot be measured
A3: Logic | B3: Molds 3362, 3343, 3352: unpack (8/31-9/3) planned before delivery (9/3) | C3: A link delivery -> unpack makes this impossible
A4: Logic | B4: Mold 3376: no TH1, TH2 on the same day as gauge validation | C4: Template always plans TH1 after gauge
A5: Logic | B5: Mold 3362: TH1 on the same day as gauge validation | C5: Template starts TH1 the workday after gauge
A6: Naming | B6: Mold 3377: press 1300-2 in some lines, 1300-3 in others | C6: Press is one input field per mold
A7: Naming | B7: Task 5.9.11 (3352) called 'TH2' but is the 30-pc Cpk | C7: Task names come from the block
A8: Resources | B8: Same person 3x: holmes / Chrisopher.holmes / christopher.holmes; Rautzenberg 3x | C8: Roles in the block, one role -> person map per project
A9: Resources | B9: A resource named 'Mold 3345: Verify correct AI Level is engraved in the mold.' | C9: Same
A10: Granularity | B10: Cpk split into 8 rows per characteristic (24 rows total) | C10: One Cpk task, characteristics as checklist from the control plan / PDB
A11: Granularity | B11: 15 iPQ element rows with identical dates and owner | C11: One ISIR/iPQ task with the element checklist
A12: Scope | B12: Mold 3360/3349/3369 changes (~55 rows) planned in the project file | C12: These are ECRs: plan them in the plm2 change plan, show only milestones here
